<mujoco model="ant">
  <compiler angle="degree" coordinate="local" inertiafromgeom="true"/>
  <option integrator="RK4" timestep="0.01"/>
  <!-- Set extent to 15 manually to match 1.5 * arena size. Required for RGBD visual because adding walls inflate the extent. -->
  <statistic extent="15" center="0 0 0"/>
  <custom>
    <numeric data="0.0 0.0 0.55 1.0 0.0 0.0 0.0 0.0 1.0 0.0 -1.0 0.0 -1.0 0.0 1.0" name="init_qpos"/>
  </custom>
  <default>
    <joint armature="1" damping="1" limited="true"/>
    <geom conaffinity="0" condim="3" density="5.0" friction="1 0.5 0.5" margin="0.01" rgba="0.8 0.6 0.4 1"/>
  </default>
  <asset>
    <texture builtin="gradient" height="100" rgb1="1 1 1" rgb2="0 0 0" type="skybox" width="100"/>
    <texture builtin="flat" height="1278" mark="cross" markrgb="1 1 1" name="texgeom" random="0.01" rgb1="0.8 0.6 0.4" rgb2="0.8 0.6 0.4" type="cube" width="127"/>
    <!-- Flat Grey Texture for the floor -->
    <texture builtin="flat" height="100" name="texgrey" rgb1="0.6 0.6 0.6" type="2d" width="100"/>
    <material name="FloorColour" reflectance="0.0" shininess="0.2" specular="0.1" rgba="0.85 0.96 0.94 1.0"/>
    <material name="geom" texture="texgeom" texuniform="true"/>

  </asset>
  <worldbody>
    <light cutoff="100" diffuse="1 1 1" dir="-0 0 -1.3" directional="true" exponent="1" pos="0 0 1.3" specular=".1 .1 .1"/>
    
    <!-- Floor: Shrunk to match arena size, now flat grey -->
    <geom conaffinity="1" condim="3" material="FloorColour" name="floor" pos="0 0 0" rgba="0.85 0.96 0.94 1.0" size="10 10 0.1" type="plane"/>
    
    <!-- Arena Walls -->
    <geom name="wall_n" pos="0 10 0.5" size="10 0.1 2" type="box" rgba="0.5 0.5 0.5 1" conaffinity="1"/>
    <geom name="wall_s" pos="0 -10 0.5" size="10 0.1 2" type="box" rgba="0.5 0.5 0.5 1" conaffinity="1"/>
    <geom name="wall_e" pos="10 0 0.5" size="0.1 10 2" type="box" rgba="0.5 0.5 0.5 1" conaffinity="1"/>
    <geom name="wall_w" pos="-10 0 0.5" size="0.1 10 2" type="box" rgba="0.5 0.5 0.5 1" conaffinity="1"/>

    <!-- Environment Camera -->
    <camera name="environment" pos="16.621 -23.302 25.771" xyaxes="0.814 0.581 -0.000 -0.389 0.545 0.743"/>

    <body name="torso" pos="0 0 0.75">
      <camera name="track" mode="trackcom" pos="0 -3 0.3" xyaxes="1 0 0 0 0 1"/>
      
      <!-- POV Camera and Marker: A small blue sphere on the torso -->
      <geom name="pov_cam_marker" pos="0.25 0 0.1" size="0.1" type="sphere" rgba="0 0 0 1" conaffinity="0" contype="0"/>
      <camera name="pov" pos="0.25 0 0.1" xyaxes="0 -1 0 0 0 1"/>
      
      <geom name="torso_geom" pos="0 0 0" size="0.25" type="sphere"/>
      <joint armature="0.0" damping="0.0" limited="false" margin="0.01" name="root" pos="0 0 0" type="free"/>
      <body name="front_left_leg" pos="0 0 0">
        <geom fromto="0.0 0.0 0.0 0.2 0.2 0.0" name="aux_1_geom" size="0.08" type="capsule"/>
        <body name="aux_1" pos="0.2 0.2 0">
          <joint axis="0 0 1" name="hip_1" pos="0.0 0.0 0.0" range="-30 30" type="hinge"/>
          <geom fromto="0.0 0.0 0.0 0.2 0.2 0.0" name="left_leg_geom" size="0.08" type="capsule"/>
          <body pos="0.2 0.2 0">
            <joint axis="-1 1 0" name="ankle_1" pos="0.0 0.0 0.0" range="30 70" type="hinge"/>
            <geom fromto="0.0 0.0 0.0 0.4 0.4 0.0" name="left_ankle_geom" size="0.08" type="capsule"/>
          </body>
        </body>
      </body>
      <body name="front_right_leg" pos="0 0 0">
        <geom fromto="0.0 0.0 0.0 -0.2 0.2 0.0" name="aux_2_geom" size="0.08" type="capsule"/>
        <body name="aux_2" pos="-0.2 0.2 0">
          <joint axis="0 0 1" name="hip_2" pos="0.0 0.0 0.0" range="-30 30" type="hinge"/>
          <geom fromto="0.0 0.0 0.0 -0.2 0.2 0.0" name="right_leg_geom" size="0.08" type="capsule"/>
          <body pos="-0.2 0.2 0">
            <joint axis="1 1 0" name="ankle_2" pos="0.0 0.0 0.0" range="-70 -30" type="hinge"/>
            <geom fromto="0.0 0.0 0.0 -0.4 0.4 0.0" name="right_ankle_geom" size="0.08" type="capsule"/>
          </body>
        </body>
      </body>
      <body name="back_leg" pos="0 0 0">
        <geom fromto="0.0 0.0 0.0 -0.2 -0.2 0.0" name="aux_3_geom" size="0.08" type="capsule"/>
        <body name="aux_3" pos="-0.2 -0.2 0">
          <joint axis="0 0 1" name="hip_3" pos="0.0 0.0 0.0" range="-30 30" type="hinge"/>
          <geom fromto="0.0 0.0 0.0 -0.2 -0.2 0.0" name="back_leg_geom" size="0.08" type="capsule"/>
          <body pos="-0.2 -0.2 0">
            <joint axis="-1 1 0" name="ankle_3" pos="0.0 0.0 0.0" range="-70 -30" type="hinge"/>
            <geom fromto="0.0 0.0 0.0 -0.4 -0.4 0.0" name="third_ankle_geom" size="0.08" type="capsule"/>
          </body>
        </body>
      </body>
      <body name="right_back_leg" pos="0 0 0">
        <geom fromto="0.0 0.0 0.0 0.2 -0.2 0.0" name="aux_4_geom" size="0.08" type="capsule"/>
        <body name="aux_4" pos="0.2 -0.2 0">
          <joint axis="0 0 1" name="hip_4" pos="0.0 0.0 0.0" range="-30 30" type="hinge"/>
          <geom fromto="0.0 0.0 0.0 0.2 -0.2 0.0" name="rightback_leg_geom" size="0.08" type="capsule"/>
          <body pos="0.2 -0.2 0">
            <joint axis="1 1 0" name="ankle_4" pos="0.0 0.0 0.0" range="30 70" type="hinge"/>
            <geom fromto="0.0 0.0 0.0 0.4 -0.4 0.0" name="fourth_ankle_geom" size="0.08" type="capsule"/>
          </body>
        </body>
      </body>
    </body>
    
    <!-- Resources for Homeostatic RL -->
    <!-- Food Sources: contype 2 (Resource), conaffinity 0 (Pass-through) -->
    <body name="food_0" pos="3 3 0.5"><geom name="food_0_geom" size="0.5" type="sphere" rgba="0 1 0 1" conaffinity="0" contype="2"/></body>
    <body name="food_1" pos="4 4 0.5"><geom name="food_1_geom" size="0.5" type="sphere" rgba="0 1 0 1" conaffinity="0" contype="2"/></body>
    <body name="food_2" pos="5 5 0.5"><geom name="food_2_geom" size="0.5" type="sphere" rgba="0 1 0 1" conaffinity="0" contype="2"/></body>
    <body name="food_3" pos="6 6 0.5"><geom name="food_3_geom" size="0.5" type="sphere" rgba="0 1 0 1" conaffinity="0" contype="2"/></body>
    <body name="food_4" pos="7 7 0.5"><geom name="food_4_geom" size="0.5" type="sphere" rgba="0 1 0 1" conaffinity="0" contype="2"/></body>

    <!-- Water Sources: contype 8 (Resource), conaffinity 0 (Pass-through) -->
    <body name="water_0" pos="-3 -3 0.5"><geom name="water_0_geom" size="0.5" type="sphere" rgba="0 0 1 1" conaffinity="0" contype="8"/></body>
    <body name="water_1" pos="-4 -4 0.5"><geom name="water_1_geom" size="0.5" type="sphere" rgba="0 0 1 1" conaffinity="0" contype="8"/></body>
    <body name="water_2" pos="-5 -5 0.5"><geom name="water_2_geom" size="0.5" type="sphere" rgba="0 0 1 1" conaffinity="0" contype="8"/></body>
    <body name="water_3" pos="-6 -6 0.5"><geom name="water_3_geom" size="0.5" type="sphere" rgba="0 0 1 1" conaffinity="0" contype="8"/></body>
    <body name="water_4" pos="-7 -7 0.5"><geom name="water_4_geom" size="0.5" type="sphere" rgba="0 0 1 1" conaffinity="0" contype="8"/></body>

    <!-- Heat Sources: contype 4 (Ghost), conaffinity 0 (Collides with nothing) -->
    <body name="heat_0" pos="0 3 0.5"><geom name="heat_0_geom" size="0.5 0.5 0.5" type="box" rgba="1 0 0 0.5" conaffinity="0" contype="4"/></body>
    <body name="heat_1" pos="0 5 0.5"><geom name="heat_1_geom" size="0.5 0.5 0.5" type="box" rgba="1 0 0 0.5" conaffinity="0" contype="4"/></body>
    <body name="heat_2" pos="0 7 0.5"><geom name="heat_2_geom" size="0.5 0.5 0.5" type="box" rgba="1 0 0 0.5" conaffinity="0" contype="4"/></body>

  </worldbody>
  <actuator>
    <motor ctrllimited="true" ctrlrange="-1.0 1.0" joint="hip_4" gear="30"/>
    <motor ctrllimited="true" ctrlrange="-1.0 1.0" joint="ankle_4" gear="30"/>
    <motor ctrllimited="true" ctrlrange="-1.0 1.0" joint="hip_1" gear="30"/>
    <motor ctrllimited="true" ctrlrange="-1.0 1.0" joint="ankle_1" gear="30"/>
    <motor ctrllimited="true" ctrlrange="-1.0 1.0" joint="hip_2" gear="30"/>
    <motor ctrllimited="true" ctrlrange="-1.0 1.0" joint="ankle_2" gear="30"/>
    <motor ctrllimited="true" ctrlrange="-1.0 1.0" joint="hip_3" gear="30"/>
    <motor ctrllimited="true" ctrlrange="-1.0 1.0" joint="ankle_3" gear="30"/>
  </actuator>
</mujoco>
